Failures in [node-test-pull-request/66753](https://ci.nodejs.org/job/node-test-pull-request/66753/) to [node-test-pull-request/66849](https://ci.nodejs.org/job/node-test-pull-request/66849/) that failed 2 or more PRs
(Generated with `ncu-ci walk pr --stats=true --markdown reports/2025-05-17.md`)

| UTC Time         | RUNNING | SUCCESS | UNSTABLE | ABORTED | FAILURE | Green Rate |
| ---------------- | ------- | ------- | -------- | ------- | ------- | ---------- |
| 2025-05-17 00:11 | 1       | 16      | 18       | 2       | 63      | 16.49%     |


### Jenkins Failure

| Reason | <code>Build timed out (after 30 minutes). Marking the build as failed.</code> |
| - | :- |
| Type | JENKINS_FAILURE |
| Failed PR | 7 ([https://github.com/nodejs/node/pull/58268/](https://ci.nodejs.org/job/node-test-pull-request/66754/), [https://github.com/nodejs/node/pull/57954/](https://ci.nodejs.org/job/node-test-pull-request/66765/), [https://github.com/nodejs/node/pull/58296/](https://ci.nodejs.org/job/node-test-pull-request/66815/), [https://github.com/nodejs/node/pull/58309/](https://ci.nodejs.org/job/node-test-pull-request/66823/), [https://github.com/nodejs/node/pull/58325/](https://ci.nodejs.org/job/node-test-pull-request/66830/), [https://github.com/nodejs/node/pull/58317/](https://ci.nodejs.org/job/node-test-pull-request/66841/), [https://github.com/nodejs/node/pull/58335/](https://ci.nodejs.org/job/node-test-pull-request/66846/)) |
| Appeared | [test-azure_msft-win11_vs2022-arm64-5](https://ci.nodejs.org/job/node-test-binary-windows-js-suites/RUN_SUBSET=3,nodes=win11-arm64-COMPILED_BY-vs2022_clang-arm64/34253/console) |
| First CI | https://ci.nodejs.org/job/node-test-pull-request/66754/ |
| Last CI | https://ci.nodejs.org/job/node-test-pull-request/66846/ |

<details>
<summary><a href="https://ci.nodejs.org/job/node-test-binary-windows-js-suites/RUN_SUBSET=3,nodes=win11-arm64-COMPILED_BY-vs2022_clang-arm64/34253/console">Example</a></summary>

```
Build timed out (after 30 minutes). Marking the build as failed.
```
</details>

-------

| Reason | <code>Build timed out (after 60 minutes). Marking the build as failed.</code> |
| - | :- |
| Type | JENKINS_FAILURE |
| Failed PR | 3 ([https://github.com/nodejs/node/pull/58165/](https://ci.nodejs.org/job/node-test-pull-request/66810/), [https://github.com/nodejs/node/pull/58307/](https://ci.nodejs.org/job/node-test-pull-request/66814/), [https://github.com/nodejs/node/pull/57909/](https://ci.nodejs.org/job/node-test-pull-request/66849/)) |
| Appeared | [test-ibm-ubi81_container-x64-1](https://ci.nodejs.org/job/node-test-commit-linux-containered/nodes=ubi81_sharedlibs_openssl111fips_x64/50691/console), [test-digitalocean-ubi81_container-x64-2](https://ci.nodejs.org/job/node-test-commit-linux-containered/nodes=ubi81_sharedlibs_openssl111fips_x64/50660/console) |
| First CI | https://ci.nodejs.org/job/node-test-pull-request/66810/ |
| Last CI | https://ci.nodejs.org/job/node-test-pull-request/66849/ |

<details>
<summary><a href="https://ci.nodejs.org/job/node-test-commit-linux-containered/nodes=ubi81_sharedlibs_openssl111fips_x64/50691/console">Example</a></summary>

```
Build timed out (after 60 minutes). Marking the build as failed.
```
</details>

-------


### Git Failure

| Reason | <code>ERROR: Error fetching remote repo 'origin'</code> |
| - | :- |
| Type | GIT_FAILURE |
| Failed PR | 4 ([https://github.com/nodejs/node/pull/58293/](https://ci.nodejs.org/job/node-test-pull-request/66773/), [https://github.com/nodejs-private/node-private/pull/708/](https://ci.nodejs.org/job/node-test-pull-request/66777/), [https://github.com/nodejs/node/pull/58269/](https://ci.nodejs.org/job/node-test-pull-request/66804/), [https://github.com/nodejs/node/pull/58237/](https://ci.nodejs.org/job/node-test-pull-request/66805/)) |
| Appeared | [test-mnx-ubuntu2204-x64-1](https://ci.nodejs.org/job/node-test-commit-linux/64645/console), [test-digitalocean-fedora40-x64-1](https://ci.nodejs.org/job/node-test-commit-linux/nodes=fedora-last-latest-x64/64606/console) |
| First CI | https://ci.nodejs.org/job/node-test-pull-request/66773/ |
| Last CI | https://ci.nodejs.org/job/node-test-pull-request/66805/ |

<details>
<summary><a href="https://ci.nodejs.org/job/node-test-commit-linux/64645/console">Example</a></summary>

```
ERROR: Error fetching remote repo 'origin'
hudson.plugins.git.GitException: Failed to fetch from git@github.com:nodejs/node.git
	at PluginClassLoader for git//hudson.plugins.git.GitSCM.fetchFrom(GitSCM.java:999)
	at PluginClassLoader for git//hudson.plugins.git.GitSCM.retrieveChanges(GitSCM.java:1240)
	at PluginClassLoader for git//hudson.plugins.git.GitSCM._checkout(GitSCM.java:1311)
	at PluginClassLoader for git//hudson.plugins.git.GitSCM.checkout(GitSCM.java:1278)
```
</details>

-------


### Build Failure

| Reason | <code>fatal: No rebase in progress?</code> |
| - | :- |
| Type | BUILD_FAILURE |
| Failed PR | 5 ([https://github.com/nodejs/node/pull/58272/](https://ci.nodejs.org/job/node-test-pull-request/66753/), [https://github.com/nodejs/node/pull/58283/](https://ci.nodejs.org/job/node-test-pull-request/66768/), [https://github.com/nodejs/node/pull/58293/](https://ci.nodejs.org/job/node-test-pull-request/66773/), [https://github.com/nodejs-private/node-private/pull/711/](https://ci.nodejs.org/job/node-test-pull-request/66788/), [https://github.com/nodejs/node/pull/58305/](https://ci.nodejs.org/job/node-test-pull-request/66848/)) |
| Appeared | [test-digitalocean-ubuntu2204-x64-2](https://ci.nodejs.org/job/node-test-commit-linux/nodes=ubuntu2204-64/64675/console), [test-ibm-ubuntu2204_sharedlibs_container-x64-1](https://ci.nodejs.org/job/node-test-commit-linux-containered/nodes=ubuntu2204_sharedlibs_shared_x64/50690/console), [test-linuxonecc-rhel9-s390x-1](https://ci.nodejs.org/job/node-test-commit-linuxone/nodes=rhel9-s390x/49436/console), [test-rackspace-debian11-x64-1](https://ci.nodejs.org/job/node-test-commit-linux/nodes=debian11-x64/64603/console), [test-mnx-ubuntu2204-x64-1](https://ci.nodejs.org/job/node-test-linter/60137/console), [test-ibm-ubuntu2204_sharedlibs_container-x64-3](https://ci.nodejs.org/job/node-test-commit-linux-containered/nodes=ubuntu2204_sharedlibs_shared_x64/50607/console) |
| First CI | https://ci.nodejs.org/job/node-test-pull-request/66753/ |
| Last CI | https://ci.nodejs.org/job/node-test-pull-request/66848/ |

<details>
<summary><a href="https://ci.nodejs.org/job/node-test-commit-linux/nodes=ubuntu2204-64/64675/console">Example</a></summary>

```
fatal: No rebase in progress?
```
</details>

-------

| Reason | <code>Failed to trigger node-test-commit</code> |
| - | :- |
| Type | BUILD_FAILURE |
| Failed PR | 3 ([https://github.com/nodejs-private/node-private/pull/711/](https://ci.nodejs.org/job/node-test-pull-request/66786/), [https://github.com/nodejs/node/pull/58209/](https://ci.nodejs.org/job/node-test-pull-request/66813/), [https://github.com/nodejs/node/pull/58327/](https://ci.nodejs.org/job/node-test-pull-request/66847/)) |
| Appeared | [test-mnx-ubuntu2204-x64-1](https://ci.nodejs.org/job/node-test-pull-request/66847/console), [test-ibm-ubuntu2204-x64-3](https://ci.nodejs.org/job/node-test-pull-request/66813/console) |
| First CI | https://ci.nodejs.org/job/node-test-pull-request/66786/ |
| Last CI | https://ci.nodejs.org/job/node-test-pull-request/66847/ |

<details>
<summary><a href="https://ci.nodejs.org/job/node-test-pull-request/66847/console">Example</a></summary>

```
Failed to trigger node-test-commit
```
</details>

-------


### JSTest Failure

| Reason | <code>pummel/test-blob-slice-with-large-size</code> |
| - | :- |
| Type | JS_TEST_FAILURE |
| Failed PR | 13 ([https://github.com/nodejs/node/pull/58180/](https://ci.nodejs.org/job/node-test-pull-request/66770/), [https://github.com/nodejs/node/pull/58332/](https://ci.nodejs.org/job/node-test-pull-request/66797/), [https://github.com/nodejs/node/pull/58303/](https://ci.nodejs.org/job/node-test-pull-request/66801/), [https://github.com/nodejs/node/pull/57954/](https://ci.nodejs.org/job/node-test-pull-request/66812/), [https://github.com/nodejs/node/pull/58296/](https://ci.nodejs.org/job/node-test-pull-request/66815/), [https://github.com/nodejs/node/pull/58171/](https://ci.nodejs.org/job/node-test-pull-request/66817/), [https://github.com/nodejs/node/pull/58309/](https://ci.nodejs.org/job/node-test-pull-request/66823/), [https://github.com/nodejs/node/pull/58307/](https://ci.nodejs.org/job/node-test-pull-request/66827/), [https://github.com/nodejs/node/pull/58325/](https://ci.nodejs.org/job/node-test-pull-request/66830/), [https://github.com/nodejs/node/pull/58349/](https://ci.nodejs.org/job/node-test-pull-request/66834/), [https://github.com/nodejs/node/pull/58317/](https://ci.nodejs.org/job/node-test-pull-request/66841/), [https://github.com/nodejs/node/pull/58335/](https://ci.nodejs.org/job/node-test-pull-request/66843/), [https://github.com/nodejs/node/pull/58305/](https://ci.nodejs.org/job/node-test-pull-request/66848/)) |
| Appeared | [test-azure_msft-win11_vs2022-x64-1](https://ci.nodejs.org/job/node-test-binary-windows-js-suites/RUN_SUBSET=0,nodes=win11-COMPILED_BY-vs2022_clang/34256/console), [test-mnx-smartos23-x64-6](https://ci.nodejs.org/job/node-test-commit-smartos/nodes=smartos23-x64/60609/console) |
| First CI | https://ci.nodejs.org/job/node-test-pull-request/66770/ |
| Last CI | https://ci.nodejs.org/job/node-test-pull-request/66848/ |

<details>
<summary><a href="https://ci.nodejs.org/job/node-test-binary-windows-js-suites/RUN_SUBSET=0,nodes=win11-COMPILED_BY-vs2022_clang/34256/console">Example</a></summary>

```
not ok 1015 pummel/test-blob-slice-with-large-size
  ---
  duration_ms: 155.66100
  severity: fail
  exitcode: 1
  stack: |-
    c:\workspace\node-test-binary-windows-js-suites\node\test\pummel\test-blob-slice-with-large-size.js:18
        throw e;
        ^
    
    RangeError: Array buffer allocation failed
        at new ArrayBuffer (<anonymous>)
        at ArrayBuffer.slice (<anonymous>)
        at getSource (node:internal/blob:125:24)
        at node:internal/blob:162:34
        at from (<anonymous>)
        at new Blob (node:internal/blob:161:22)
        at Object.<anonymous> (c:\workspace\node-test-binary-windows-js-suites\node\test\pummel\test-blob-slice-with-large-size.js:13:16)
        at Module._compile (node:internal/modules/cjs/loader:1734:14)
        at Object..js (node:internal/modules/cjs/loader:1899:10)
        at Module.load (node:internal/modules/cjs/loader:1469:32)
    
    Node.js v25.0.0-pre
  ...

```
</details>

-------

| Reason | <code>parallel/test-buffer-tostring-range</code> |
| - | :- |
| Type | JS_TEST_FAILURE |
| Failed PR | 8 ([https://github.com/nodejs/node/pull/58332/](https://ci.nodejs.org/job/node-test-pull-request/66797/), [https://github.com/nodejs/node/pull/58303/](https://ci.nodejs.org/job/node-test-pull-request/66801/), [https://github.com/nodejs/node/pull/58171/](https://ci.nodejs.org/job/node-test-pull-request/66806/), [https://github.com/nodejs/node/pull/58307/](https://ci.nodejs.org/job/node-test-pull-request/66827/), [https://github.com/nodejs/node/pull/58349/](https://ci.nodejs.org/job/node-test-pull-request/66834/), [https://github.com/nodejs/node/pull/58317/](https://ci.nodejs.org/job/node-test-pull-request/66841/), [https://github.com/nodejs/node/pull/58335/](https://ci.nodejs.org/job/node-test-pull-request/66846/), [https://github.com/nodejs/node/pull/58305/](https://ci.nodejs.org/job/node-test-pull-request/66848/)) |
| Appeared | [test-azure_msft-win11_vs2022-x64-1](https://ci.nodejs.org/job/node-test-binary-windows-js-suites/RUN_SUBSET=0,nodes=win11-COMPILED_BY-vs2022/34251/console) |
| First CI | https://ci.nodejs.org/job/node-test-pull-request/66797/ |
| Last CI | https://ci.nodejs.org/job/node-test-pull-request/66848/ |

<details>
<summary><a href="https://ci.nodejs.org/job/node-test-binary-windows-js-suites/RUN_SUBSET=0,nodes=win11-COMPILED_BY-vs2022/34251/console">Example</a></summary>

```
not ok 114 parallel/test-buffer-tostring-range
  ---
  duration_ms: 145.00800
  severity: fail
  exitcode: 1
  stack: |-
    node:internal/buffer:961
        super(bufferOrLength, byteOffset, length);
        ^
    
    RangeError: Array buffer allocation failed
        at new ArrayBuffer (<anonymous>)
        at new Uint8Array (<anonymous>)
        at new FastBuffer (node:internal/buffer:961:5)
        at Function.alloc (node:buffer:400:10)
        at Object.<anonymous> (c:\workspace\node-test-binary-windows-js-suites\node\test\parallel\test-buffer-tostring-range.js:107:28)
        at Module._compile (node:internal/modules/cjs/loader:1730:14)
        at Object..js (node:internal/modules/cjs/loader:1895:10)
        at Module.load (node:internal/modules/cjs/loader:1465:32)
        at Function._load (node:internal/modules/cjs/loader:1282:12)
        at TracingChannel.traceSync (node:diagnostics_channel:322:14)
    
    Node.js v22.15.1-pre
  ...

```
</details>

-------

| Reason | <code>parallel/test-http2-debug</code> |
| - | :- |
| Type | JS_TEST_FAILURE |
| Failed PR | 6 ([https://github.com/nodejs/node/pull/58124/](https://ci.nodejs.org/job/node-test-pull-request/66824/), [https://github.com/nodejs/node/pull/58349/](https://ci.nodejs.org/job/node-test-pull-request/66834/), [https://github.com/nodejs/node/pull/58350/](https://ci.nodejs.org/job/node-test-pull-request/66842/), [https://github.com/nodejs/node/pull/58357/](https://ci.nodejs.org/job/node-test-pull-request/66845/), [https://github.com/nodejs/node/pull/58305/](https://ci.nodejs.org/job/node-test-pull-request/66848/), [https://github.com/nodejs/node/pull/57909/](https://ci.nodejs.org/job/node-test-pull-request/66849/)) |
| Appeared | [test-ibm-rhel8-s390x-1](https://ci.nodejs.org/job/node-test-commit-linuxone/nodes=rhel8-s390x/49493/console), [test-linuxonecc-rhel9-s390x-1](https://ci.nodejs.org/job/node-test-commit-linuxone/nodes=rhel9-s390x/49492/console), [test-ibm-rhel8-s390x-4](https://ci.nodejs.org/job/node-test-commit-linuxone/nodes=rhel8-s390x/49491/console) |
| First CI | https://ci.nodejs.org/job/node-test-pull-request/66824/ |
| Last CI | https://ci.nodejs.org/job/node-test-pull-request/66849/ |

<details>
<summary><a href="https://ci.nodejs.org/job/node-test-commit-linuxone/nodes=rhel8-s390x/49493/console">Example</a></summary>

```
not ok 1632 parallel/test-http2-debug
  ---
  duration_ms: 201.61600
  severity: fail
  exitcode: 1
  stack: |-
    node:internal/assert/utils:281
        throw err;
        ^
    
    AssertionError [ERR_ASSERTION]: HTTP2 1981824: Http2Session client: created
    (node:1981824) Warning: Setting the NODE_DEBUG environment variable to 'http2' can expose sensitive data (such as passwords, tokens and authentication headers) in the resulting log.
    (Use `node --trace-warnings ...` to show where the warning was created)
    HTTP2 1981824: Http2Session server: received a connection
    HTTP2 1981824: Http2Session server: setting up session handle
    Http2Session server (14) session created
    Http2Session server (14) i/o stream consumed
    HTTP2 1981824: Http2Session server: sending settings
    HTTP2 1981824: Http2Session server: submitting settings
    Http2Session server (14) scheduling write
    HTTP2 1981824: Http2Session server: created
    HTTP2 1981824: Http2Session client: setting up session handle
  ...
```
</details>

-------

| Reason | <code>sequential/test-tls-session-timeout</code> |
| - | :- |
| Type | JS_TEST_FAILURE |
| Failed PR | 5 ([https://github.com/nodejs/node/pull/58268/](https://ci.nodejs.org/job/node-test-pull-request/66754/), [https://github.com/nodejs/node/pull/57861/](https://ci.nodejs.org/job/node-test-pull-request/66763/), [https://github.com/nodejs-private/node-private/pull/708/](https://ci.nodejs.org/job/node-test-pull-request/66777/), [https://github.com/nodejs-private/node-private/pull/714/](https://ci.nodejs.org/job/node-test-pull-request/66791/), [https://github.com/nodejs/node/pull/58324/](https://ci.nodejs.org/job/node-test-pull-request/66820/)) |
| Appeared | [test-ibm-ubuntu2204_sharedlibs_container-x64-5](https://ci.nodejs.org/job/node-test-commit-linux-containered/nodes=ubuntu2204_sharedlibs_openssl35_x64/50665/console), [test-ibm-ubuntu2204_sharedlibs_container-x64-4](https://ci.nodejs.org/job/node-test-commit-linux-containered/nodes=ubuntu2204_sharedlibs_openssl35_x64/50634/console) |
| First CI | https://ci.nodejs.org/job/node-test-pull-request/66754/ |
| Last CI | https://ci.nodejs.org/job/node-test-pull-request/66820/ |

<details>
<summary><a href="https://ci.nodejs.org/job/node-test-commit-linux-containered/nodes=ubuntu2204_sharedlibs_openssl35_x64/50665/console">Example</a></summary>

```
not ok 4444 sequential/test-tls-session-timeout
  ---
  duration_ms: 212.31900
  severity: fail
  exitcode: 1
  stack: |-
    node:assert:94
      throw new AssertionError(obj);
      ^
    
    AssertionError [ERR_ASSERTION]: Expected values to be strictly equal:
    
    'New' !== 'Reused'
    
        at /home/iojs/build/workspace/node-test-commit-linux-containered/test/sequential/test-tls-session-timeout.js:150:16
        at ChildProcess.<anonymous> (/home/iojs/build/workspace/node-test-commit-linux-containered/test/sequential/test-tls-session-timeout.js:134:7)
        at ChildProcess.emit (node:events:507:28)
        at ChildProcess._handle.onexit (node:internal/child_process:294:12) {
      generatedMessage: true,
      code: 'ERR_ASSERTION',
      actual: 'New',
      expected: 'Reused',
      operator: 'strictEqual'
    }
    
    Node.js v25.0.0-pre
  ...

```
</details>

-------

| Reason | <code>parallel/test-crypto-async-sign-verify</code> |
| - | :- |
| Type | JS_TEST_FAILURE |
| Failed PR | 4 ([https://github.com/nodejs-private/node-private/pull/712/](https://ci.nodejs.org/job/node-test-pull-request/66778/), [https://github.com/nodejs-private/node-private/pull/714/](https://ci.nodejs.org/job/node-test-pull-request/66781/), [https://github.com/nodejs-private/node-private/pull/711/](https://ci.nodejs.org/job/node-test-pull-request/66788/), [https://github.com/nodejs-private/node-private/pull/708/](https://ci.nodejs.org/job/node-test-pull-request/66790/)) |
| Appeared | [test-ibm-ubuntu2204_sharedlibs_container-x64-5](https://ci.nodejs.org/job/node-test-commit-linux-containered/nodes=ubuntu2204_sharedlibs_openssl35_x64/50630/console), [test-azure_msft-win11_vs2022-arm64-2](https://ci.nodejs.org/job/node-test-binary-windows-js-suites/RUN_SUBSET=2,nodes=win11-arm64-COMPILED_BY-vs2022_clang-arm64/34190/console), [test-azure_msft-win10_vs2019-x64-3](https://ci.nodejs.org/job/node-test-binary-windows-js-suites/RUN_SUBSET=3,nodes=win10-COMPILED_BY-vs2022_clang/34190/console), [test-azure_msft-win11_vs2022-x64-4](https://ci.nodejs.org/job/node-test-binary-windows-js-suites/RUN_SUBSET=3,nodes=win11-COMPILED_BY-vs2022_clang/34190/console), [test-rackspace-win2019_vs2019-x64-4](https://ci.nodejs.org/job/node-test-binary-windows-js-suites/RUN_SUBSET=3,nodes=win2019-COMPILED_BY-vs2022_clang/34190/console), [test-rackspace-win2022_vs2022-x64-2](https://ci.nodejs.org/job/node-test-binary-windows-js-suites/RUN_SUBSET=3,nodes=win2022-COMPILED_BY-vs2022_clang/34190/console), [test-ibm-ubi81_container-x64-1](https://ci.nodejs.org/job/node-test-commit-linux-containered/nodes=ubi81_sharedlibs_openssl111fips_x64/50628/console), [test-digitalocean-ubuntu2204_sharedlibs_container-x64-4](https://ci.nodejs.org/job/node-test-commit-linux-containered/nodes=ubuntu2204_sharedlibs_openssl111_x64/50628/console), [test-ibm-ubuntu2204_sharedlibs_container-x64-2](https://ci.nodejs.org/job/node-test-commit-linux-containered/nodes=ubuntu2204_sharedlibs_openssl111_x64/50620/console), [test-digitalocean-ubuntu2204_sharedlibs_container-x64-2](https://ci.nodejs.org/job/node-test-commit-linux-containered/nodes=ubuntu2204_sharedlibs_openssl111_x64/50619/console) |
| First CI | https://ci.nodejs.org/job/node-test-pull-request/66778/ |
| Last CI | https://ci.nodejs.org/job/node-test-pull-request/66790/ |

<details>
<summary><a href="https://ci.nodejs.org/job/node-test-commit-linux-containered/nodes=ubuntu2204_sharedlibs_openssl35_x64/50630/console">Example</a></summary>

```
not ok 778 parallel/test-crypto-async-sign-verify
  ---
  duration_ms: 187.93700
  severity: fail
  exitcode: 1
  stack: |-
    /home/iojs/build/workspace/node-test-commit-linux-containered/test/common/index.js:1003
          throw new Error(`Using invalid common property: '${prop}'`);
          ^
    
    Error: Using invalid common property: 'hasOpenSSL3'
        at Object.get (/home/iojs/build/workspace/node-test-commit-linux-containered/test/common/index.js:1003:13)
        at Object.<anonymous> (/home/iojs/build/workspace/node-test-commit-linux-containered/test/parallel/test-crypto-async-sign-verify.js:152:27)
        at Module._compile (node:internal/modules/cjs/loader:1734:14)
        at Object..js (node:internal/modules/cjs/loader:1899:10)
        at Module.load (node:internal/modules/cjs/loader:1469:32)
        at Module._load (node:internal/modules/cjs/loader:1286:12)
        at TracingChannel.traceSync (node:diagnostics_channel:322:14)
        at wrapModuleLoad (node:internal/modules/cjs/loader:235...
```
</details>

-------

| Reason | <code>parallel/test-cluster-fork-stdio</code> |
| - | :- |
| Type | JS_TEST_FAILURE |
| Failed PR | 3 ([https://github.com/nodejs/node/pull/58268/](https://ci.nodejs.org/job/node-test-pull-request/66754/), [https://github.com/nodejs/node/pull/57954/](https://ci.nodejs.org/job/node-test-pull-request/66765/), [https://github.com/nodejs/node/pull/58335/](https://ci.nodejs.org/job/node-test-pull-request/66816/)) |
| Appeared | [test-rackspace-win2022_vs2022-x64-5](https://ci.nodejs.org/job/node-test-binary-windows-js-suites/RUN_SUBSET=2,nodes=win2022-COMPILED_BY-vs2022_clang/34221/console), [test-rackspace-win2019_vs2019-x64-2](https://ci.nodejs.org/job/node-test-binary-windows-js-suites/RUN_SUBSET=1,nodes=win2019-COMPILED_BY-vs2022/34057/console) |
| First CI | https://ci.nodejs.org/job/node-test-pull-request/66754/ |
| Last CI | https://ci.nodejs.org/job/node-test-pull-request/66816/ |

<details>
<summary><a href="https://ci.nodejs.org/job/node-test-binary-windows-js-suites/RUN_SUBSET=2,nodes=win2022-COMPILED_BY-vs2022_clang/34221/console">Example</a></summary>

```
not ok 1007 parallel/test-cluster-fork-stdio
  ---
  duration_ms: 120184.86000
  severity: fail
  exitcode: 1
  stack: |-
    timeout
  ...

```
</details>

-------

| Reason | <code>parallel/test-async-context-frame</code> |
| - | :- |
| Type | JS_TEST_FAILURE |
| Failed PR | 2 ([https://github.com/nodejs-private/node-private/pull/712/](https://ci.nodejs.org/job/node-test-pull-request/66778/), [https://github.com/nodejs-private/node-private/pull/708/](https://ci.nodejs.org/job/node-test-pull-request/66790/)) |
| Appeared | [test-digitalocean-ubuntu2204_sharedlibs_container-x64-1](https://ci.nodejs.org/job/node-test-commit-linux-containered/nodes=ubuntu2204_sharedlibs_shared_x64/50633/console), [test-digitalocean-ubuntu2204_sharedlibs_container-x64-4](https://ci.nodejs.org/job/node-test-commit-linux-containered/nodes=ubuntu2204_sharedlibs_shared_x64/50620/console) |
| First CI | https://ci.nodejs.org/job/node-test-pull-request/66778/ |
| Last CI | https://ci.nodejs.org/job/node-test-pull-request/66790/ |

<details>
<summary><a href="https://ci.nodejs.org/job/node-test-commit-linux-containered/nodes=ubuntu2204_sharedlibs_shared_x64/50633/console">Example</a></summary>

```
not ok 266 parallel/test-async-context-frame
  ---
  duration_ms: 120046.66500
  severity: fail
  exitcode: -15
  stack: |-
    timeout
  ...

```
</details>

-------

| Reason | <code>parallel/test-buffer-tostring-rangeerror</code> |
| - | :- |
| Type | JS_TEST_FAILURE |
| Failed PR | 2 ([https://github.com/nodejs/node/pull/57954/](https://ci.nodejs.org/job/node-test-pull-request/66765/), [https://github.com/nodejs-private/node-private/pull/711/](https://ci.nodejs.org/job/node-test-pull-request/66788/)) |
| Appeared | [test-rackspace-win2019_vs2019-x64-2](https://ci.nodejs.org/job/node-test-binary-windows-js-suites/RUN_SUBSET=2,nodes=win2019-COMPILED_BY-vs2019/34191/console), [test-rackspace-win2019_vs2019-x64-1](https://ci.nodejs.org/job/node-test-binary-windows-js-suites/RUN_SUBSET=2,nodes=win2019-COMPILED_BY-vs2019/34189/console) |
| First CI | https://ci.nodejs.org/job/node-test-pull-request/66765/ |
| Last CI | https://ci.nodejs.org/job/node-test-pull-request/66788/ |

<details>
<summary><a href="https://ci.nodejs.org/job/node-test-binary-windows-js-suites/RUN_SUBSET=2,nodes=win2019-COMPILED_BY-vs2019/34191/console">Example</a></summary>

```
not ok 103 parallel/test-buffer-tostring-rangeerror
  ---
  duration_ms: 335.03600
  severity: fail
  exitcode: 1
  stack: |-
    node:assert:377
          throw err;
          ^
    
    AssertionError [ERR_ASSERTION]: Expected values to be strictly deep-equal:
    + actual - expected
    
      Comparison {
    +   name: 'RangeError'
    -   code: 'ERR_STRING_TOO_LONG',
    -   name: 'Error'
      }
        at Object.<anonymous> (C:\workspace\node-test-binary-windows-js-suites\node\test\parallel\test-buffer-tostring-rangeerror.js:21:8)
        at Module._compile (node:internal/modules/cjs/loader:1529:14)
        at Module._extensions..js (node:internal/modules/cjs/loader:1613:10)
        at Module.load (node:internal/modules/cjs/loader:1275:32)
        at Module._load (node:internal/modules/cjs/loader:1096:12)
        at Function.executeUserEntryPoint [as runMain] (node:internal/modules/run_main:164:12)
        at node:internal/main/run_main_module:28:49 {
      generatedMessage: true,
      code: 'ERR_ASSE...
```
</details>

-------

| Reason | <code>parallel/test-esm-loader-hooks-inspect-wait</code> |
| - | :- |
| Type | JS_TEST_FAILURE |
| Failed PR | 2 ([https://github.com/nodejs-private/node-private/pull/711/](https://ci.nodejs.org/job/node-test-pull-request/66787/), [https://github.com/nodejs/node/pull/58325/](https://ci.nodejs.org/job/node-test-pull-request/66803/)) |
| Appeared | [vm-jc8l6](https://ci.nodejs.org/job/node-test-commit-osx/nodes=osx13-x64/65083/console), [test-digitalocean-freebsd13-x64-1](https://ci.nodejs.org/job/node-test-commit-freebsd/nodes=freebsd13-x64/60154/console) |
| First CI | https://ci.nodejs.org/job/node-test-pull-request/66787/ |
| Last CI | https://ci.nodejs.org/job/node-test-pull-request/66803/ |

<details>
<summary><a href="https://ci.nodejs.org/job/node-test-commit-osx/nodes=osx13-x64/65083/console">Example</a></summary>

```
not ok 810 parallel/test-esm-loader-hooks-inspect-wait
  ---
  duration_ms: 1906.11600
  severity: fail
  exitcode: 1
  stack: |-
    [test] Connecting to a child Node process
    [test] Testing /json/list
    [err] Debugger listening on ws://127.0.0.1:63865/5aa627de-29bc-4a83-a19f-fd61750cbc6a
    [err] For help, see: https://nodejs.org/en/docs/inspector
    [err] 
    [err] Debugger attached.
    [err] 
    [err] Waiting for the debugger to disconnect...
    [err] 
    [err] child process crashed, signal SIGSEGV
    AssertionError [ERR_ASSERTION]: Expected values to be strictly equal:
    
    null !== 0
    
        at runTest (/Users/admin/build/workspace/node-test-commit-osx/nodes/osx13-x64/test/parallel/test-esm-loader-hooks-inspect-wait.js:27:10)
        at process.processTicksAndRejections (node:internal/process/task_queues:105:5) {
      generatedMessage: true,
      code: 'ERR_ASSERTION',
      actual: null,
      expected: 0,
      operator: 'strictEqual'
    }
    1
  ...

```
</details>

-------

| Reason | <code>parallel/test-http-server-headers-timeout-keepalive</code> |
| - | :- |
| Type | JS_TEST_FAILURE |
| Failed PR | 2 ([https://github.com/nodejs/node/pull/58327/](https://ci.nodejs.org/job/node-test-pull-request/66809/), [https://github.com/nodejs/node/pull/58306/](https://ci.nodejs.org/job/node-test-pull-request/66811/)) |
| Appeared | [test-ibm-rhel8-s390x-3](https://ci.nodejs.org/job/node-test-commit-linuxone/nodes=rhel8-s390x/49466/console), [test-ibm-rhel8-s390x-2](https://ci.nodejs.org/job/node-test-commit-linuxone/nodes=rhel8-s390x/49464/console) |
| First CI | https://ci.nodejs.org/job/node-test-pull-request/66809/ |
| Last CI | https://ci.nodejs.org/job/node-test-pull-request/66811/ |

<details>
<summary><a href="https://ci.nodejs.org/job/node-test-commit-linuxone/nodes=rhel8-s390x/49466/console">Example</a></summary>

```
not ok 1488 parallel/test-http-server-headers-timeout-keepalive
  ---
  duration_ms: 16672.76800
  severity: fail
  exitcode: 1
  stack: |-
    node:assert:94
      throw new AssertionError(obj);
      ^
    
    AssertionError [ERR_ASSERTION]: Expected values to be strictly equal:
    + actual - expected
    
    + 'HTTP/1.1 200 OK\r\n' +
    +   'Content-Type: text/plain\r\n' +
    +   'Date: Thu, 15 May 2025 15:00:47 GMT\r\n' +
    +   'Connection: close\r\n' +
    +   'Transfer-Encoding: chunked\r\n' +
    +   '\r\n' +
    +   '0\r\n' +
    +   '\r\n'
    - 'HTTP/1.1 408 Request Timeout\r\nConnection: close\r\n\r\n'
    
        at Socket.<anonymous> (/home/iojs/build/workspace/node-test-commit-linuxone/test/parallel/test-http-server-headers-timeout-keepalive.js:82:12)
        at Socket.<anonymous> (/home/iojs/build/workspace/node-test-commit-linuxone/test/common/index.js:437:15)
        at Socket.emit (node:events:519:35)
        at endReadableNT (node:internal/streams/readable:1701:12)
        at proces...
```
</details>

-------

| Reason | <code>parallel/test-runner-run-watch</code> |
| - | :- |
| Type | JS_TEST_FAILURE |
| Failed PR | 2 ([https://github.com/nodejs/node/pull/58268/](https://ci.nodejs.org/job/node-test-pull-request/66754/), [https://github.com/nodejs/node/pull/58165/](https://ci.nodejs.org/job/node-test-pull-request/66810/)) |
| Appeared | [vm-gxfks](https://ci.nodejs.org/job/node-test-commit-osx/nodes=osx13-x64/65090/console), [vm-5xl77](https://ci.nodejs.org/job/node-test-commit-osx/nodes=osx13-x64/65030/console) |
| First CI | https://ci.nodejs.org/job/node-test-pull-request/66754/ |
| Last CI | https://ci.nodejs.org/job/node-test-pull-request/66810/ |

<details>
<summary><a href="https://ci.nodejs.org/job/node-test-commit-osx/nodes=osx13-x64/65090/console">Example</a></summary>

```
not ok 2635 parallel/test-runner-run-watch
  ---
  duration_ms: 23087.85200
  severity: fail
  exitcode: 1
  stack: |-
    Test failure: 'should run with different cwd while in watch mode and isolation "none"'
    Location: test/parallel/test-runner-run-watch.mjs:308:5
    AssertionError [ERR_ASSERTION]: function should not have been called at file:///Users/admin/build/workspace/node-test-commit-osx/nodes/osx13-x64/test/parallel/test-runner-run-watch.mjs:323
    called with arguments: [Object: null prototype] {
      name: '<anonymous>',
      nesting: 0,
      testNumber: 1,
      details: [Object: null prototype] {
        duration_ms: 230.051728,
        type: 'test',
        error: [Error: test failed] {
          code: 'ERR_TEST_FAILURE',
          failureType: 'testCodeFailure',
          cause: 'test failed',
          exitCode: null,
          signal: 'SIGTERM'
        }
      },
      line: 1,
      column: 1,
      file: '/Users/admin/build/workspace/node-test-commit-osx/nodes/osx13-x64/<anonymous>'...
```
</details>

-------

| Reason | <code>parallel/test-stream-readable-to-web</code> |
| - | :- |
| Type | JS_TEST_FAILURE |
| Failed PR | 2 ([https://github.com/nodejs/node/pull/57903/](https://ci.nodejs.org/job/node-test-pull-request/66761/), [https://github.com/nodejs/node/pull/58317/](https://ci.nodejs.org/job/node-test-pull-request/66822/)) |
| Appeared | [test-ibm-rhel8-s390x-1](https://ci.nodejs.org/job/node-test-commit-linuxone/nodes=rhel8-s390x/49473/console), [test-linuxonecc-rhel9-s390x-1](https://ci.nodejs.org/job/node-test-commit-linuxone/nodes=rhel9-s390x/49409/console) |
| First CI | https://ci.nodejs.org/job/node-test-pull-request/66761/ |
| Last CI | https://ci.nodejs.org/job/node-test-pull-request/66822/ |

<details>
<summary><a href="https://ci.nodejs.org/job/node-test-commit-linuxone/nodes=rhel8-s390x/49473/console">Example</a></summary>

```
not ok 3685 parallel/test-stream-readable-to-web
  ---
  duration_ms: 120056.72200
  severity: fail
  exitcode: -15
  stack: |-
    timeout
  ...

```
</details>

-------

| Reason | <code>parallel/test-worker-nearheaplimit-deadlock</code> |
| - | :- |
| Type | JS_TEST_FAILURE |
| Failed PR | 2 ([https://github.com/nodejs/node/pull/58293/](https://ci.nodejs.org/job/node-test-pull-request/66773/), [https://github.com/nodejs/node/pull/58324/](https://ci.nodejs.org/job/node-test-pull-request/66799/)) |
| Appeared | [test-equinix-rhel8_container-arm64-2](https://ci.nodejs.org/job/node-test-commit-arm/nodes=rhel8-arm64/58524/console), [test-equinix-rhel8_container-arm64-1](https://ci.nodejs.org/job/node-test-commit-arm/nodes=rhel8-arm64/58493/console) |
| First CI | https://ci.nodejs.org/job/node-test-pull-request/66773/ |
| Last CI | https://ci.nodejs.org/job/node-test-pull-request/66799/ |

<details>
<summary><a href="https://ci.nodejs.org/job/node-test-commit-arm/nodes=rhel8-arm64/58524/console">Example</a></summary>

```
not ok 3925 parallel/test-worker-nearheaplimit-deadlock
  ---
  duration_ms: 510.91900
  severity: crashed
  exitcode: -6
  stack: |-
    
    <--- Last few GCs --->
    
    [3529142:0xffffadac0000]       23 ms: Mark-Compact 1.3 (3.8) -> 1.3 (3.8) MB, pooled: 0 MB, 1.55 / 0.00 ms  (average mu = 0.598, current mu = 0.019) background allocation failure; GC in old space requested
    [3529142:0xffffadac0000]       24 ms: Mark-Compact 1.3 (3.8) -> 1.3 (3.8) MB, pooled: 0 MB, 1.26 / 0.00 ms  (average mu = 0.469, current mu = 0.072) background allocation failure; GC in old space requested
    
    FATAL ERROR: CALL_AND_RETRY_LAST Allocation failed - JavaScript heap out of memory
    ----- Native stack trace -----
    
     1: 0xecdb60 node::OOMErrorHandler(char const*, v8::OOMDetails const&) [out/Release/node]
     2: 0x128c4bc v8::Utils::ReportOOMFailure(v8::internal::Isolate*, char const*, v8::OOMDetails const&) [out/Release/node]
     3: 0x128c594 v8::internal::V8::FatalProcessOutOfMemory(v8::internal::Isolate*...
```
</details>

-------

| Reason | <code>sequential/test-perf-hooks</code> |
| - | :- |
| Type | JS_TEST_FAILURE |
| Failed PR | 2 ([https://github.com/nodejs-private/node-private/pull/712/](https://ci.nodejs.org/job/node-test-pull-request/66778/), [https://github.com/nodejs/node/pull/58357/](https://ci.nodejs.org/job/node-test-pull-request/66845/)) |
| Appeared | [test-digitalocean-alpine321_container-x64-1](https://ci.nodejs.org/job/node-test-commit-linux/nodes=alpine-latest-x64/64674/console), [test-ibm-ubuntu2204_sharedlibs_container-x64-3](https://ci.nodejs.org/job/node-test-commit-linux-containered/nodes=ubuntu2204_sharedlibs_openssl32_x64/50620/console) |
| First CI | https://ci.nodejs.org/job/node-test-pull-request/66778/ |
| Last CI | https://ci.nodejs.org/job/node-test-pull-request/66845/ |

<details>
<summary><a href="https://ci.nodejs.org/job/node-test-commit-linux/nodes=alpine-latest-x64/64674/console">Example</a></summary>

```
not ok 4471 sequential/test-perf-hooks
  ---
  duration_ms: 275.75100
  severity: fail
  exitcode: 1
  stack: |-
    check initial nodeTiming
    {
      "name": "node",
      "entryType": "node",
      "startTime": 0,
      "duration": 164.314031,
      "nodeStart": 1.0216879844665527,
      "v8Start": 25.673814296722412,
      "environment": 57.547940254211426,
      "loopStart": -1,
      "loopExit": -1,
      "bootstrapComplete": 82.52445697784424,
      "idleTime": 0,
      "uvMetricsInfo": {
        "loopCount": 0,
        "events": 0,
        "eventsWaiting": 0
      }
    }
    node:internal/assert/utils:281
        throw err;
        ^
    
    AssertionError [ERR_ASSERTION]: now (174.635695) - timing.duration (164.314031) = 10.321663999999998 >= 10
        at checkNodeTiming (/home/iojs/build/workspace/node/test/sequential/test-perf-hooks.js:61:3)
        at Object.<anonymous> (/home/iojs/build/workspace/node/test/sequential/test-perf-hooks.js:78:1)
        at Module._compile (node:internal/modules/...
```
</details>

-------

| Reason | <code>sequential/test-performance-eventloopdelay</code> |
| - | :- |
| Type | JS_TEST_FAILURE |
| Failed PR | 2 ([https://github.com/nodejs-private/node-private/pull/711/](https://ci.nodejs.org/job/node-test-pull-request/66793/), [https://github.com/nodejs/node/pull/58001/](https://ci.nodejs.org/job/node-test-pull-request/66802/)) |
| Appeared | [test-ibm-rhel8-s390x-4](https://ci.nodejs.org/job/node-test-commit-linuxone/nodes=rhel8-s390x/49457/console), [test-linuxonecc-rhel9-s390x-4](https://ci.nodejs.org/job/node-test-commit-linuxone/nodes=rhel9-s390x/49441/console), [test-linuxonecc-rhel9-s390x-3](https://ci.nodejs.org/job/node-test-commit-linuxone/nodes=rhel9-s390x/49435/console) |
| First CI | https://ci.nodejs.org/job/node-test-pull-request/66793/ |
| Last CI | https://ci.nodejs.org/job/node-test-pull-request/66802/ |

<details>
<summary><a href="https://ci.nodejs.org/job/node-test-commit-linuxone/nodes=rhel8-s390x/49457/console">Example</a></summary>

```
not ok 4438 sequential/test-performance-eventloopdelay
  ---
  duration_ms: 14731.00300
  severity: fail
  exitcode: 1
  stack: |-
    node:internal/assert/utils:281
        throw err;
        ^
    
    AssertionError [ERR_ASSERTION]: The expression evaluated to a falsy value:
    
      assert(histogram.min > 0)
    
        at Timeout.spinAWhile [as _onTimeout] (/home/iojs/build/workspace/node-test-commit-linuxone/test/sequential/test-performance-eventloopdelay.js:70:7)
        at listOnTimeout (node:internal/timers:608:17)
        at process.processTimers (node:internal/timers:543:7) {
      generatedMessage: true,
      code: 'ERR_ASSERTION',
      actual: false,
      expected: true,
      operator: '=='
    }
    
    Node.js v25.0.0-pre
  ...

```
</details>

-------

